---
layout: mypost
title: Promise的基本用法
categories: [javascript]
---

# 特点
1. promise有3种状态：pending（进行中）、fulfilled（已成功）和rejected（已失败）。
2. Promise对象的状态改变，只有两种可能：从pending变为fulfilled和从pending变为rejected。只要这两种情况发生，状态就不会再变了。

# 基本用法
```
const promise = new Promise(function(resolve, reject) {
  // ... some code

  if (/* 异步操作成功 */){
	//resolve函数的作用是，将Promise对象的状态从“未完成”变为“成功”（即从 pending 变为 resolved）
    resolve(value);
  } else {
	//reject函数的作用是，将Promise对象的状态从“未完成”变为“失败”（即从 pending 变为 rejected）
    reject(error);
  }
});

//then的两个参数分别是成功和失败的回调，其中第二个参数可选
promise.then(function(value) {
  // success
}, function(error) {
  // failure
});
```


*Promise 新建后就会立即执行，then会在当前脚本所有同步任务执行完才会执行*
```
let promise = new Promise(function(resolve, reject) {
//调用resolve或reject并不会终结 Promise 的参数函数的执行。
//下面的1会继续输出
//如果希望终止执行，可以return resolve();
  resolve();
  console.log(1);
});

promise.then(function() {
  console.log(2);
});

console.log(3);

// 1
// 3
// 2
```


*一个promise是另一个promise的参数的情况*
```
const p1 = new Promise(function (resolve, reject) {
  setTimeout(() => reject(new Error('fail')), 3000)
})

const p2 = new Promise(function (resolve, reject) {
  setTimeout(() => resolve(p1), 1000)
})

p2
  .then(result => console.log(result))
  .catch(error => console.log(error))
// 结果会运行catch，输出Error: fail
```
p1和p2都是 Promise 的实例，但是p2的resolve方法将p1作为参数，即一个异步操作的结果是返回另一个异步操作。

注意，这时p1的状态就会传递给p2，也就是说，p1的状态决定了p2的状态。如果p1的状态是pending，那么p2的回调函数就会等待p1的状态改变；如果p1的状态已经是resolved或者rejected，那么p2的回调函数将会立刻执行。

上面代码中，p1是一个 Promise，3 秒之后变为rejected。p2的状态在 1 秒之后改变，resolve方法返回的是p1。由于p2返回的是另一个 Promise，导致p2自己的状态无效了，由p1的状态决定p2的状态。所以，后面的then语句都变成针对后者（p1）。又过了 2 秒，p1变为rejected，导致触发catch方法指定的回调函数。


# 多个then的链式调用
```
getJSON("/post/1.json").then(
  post => getJSON(post.commentURL)
).then(
  comments => console.log("resolved: ", comments),
  err => console.log("rejected: ", err)
);
```
上面代码中，第一个then中又进行了异步操作，返回promise对象，这时后面的函数会等待这个新的Promise对象状态发生变化。如果变为resolved，就调用comments...，如果状态变为rejected，就调用err...。

其他demo
```
new Promise((resolve, reject) => {
	setTimeout(function(){resolve()},2000);
}).then(
	() => {
		console.log(1);
		//这里记得return出Promise实例，否则后面会输出2
		return new Promise((resolve,reject) => {
			setTimeout(function(){reject()},3000);
		})
	}
).then(
	() => console.log(2),
	() => console.log(3)
)
// 1
// 3
```


# catch

Promise.prototype.catch方法是.then(null, rejection)的别名，用于指定发生错误时的回调函数。

*如果 Promise 状态已经变成resolved，再抛出错误是无效的。*
```
const promise = new Promise(function(resolve, reject) {
	resolve('ok');
	throw new Error('test');
});
promise
	.then(function(value) { console.log(value) })
	.catch(function(error) { console.log(error) });
// ok
```
上面代码中，Promise 在resolve语句后面，再抛出错误，不会被捕获，等于没有抛出。因为 Promise 的状态一旦改变，就永久保持该状态，不会再变了。


*Promise 对象的错误具有“冒泡”性质，会一直向后传递，直到被捕获为止。也就是说，错误总是会被下一个catch语句捕获。*
```
getJSON('/post/1.json').then(function(post) {
	return getJSON(post.commentURL);
}).then(function(comments) {
	// some code
}).catch(function(error) {
	// 处理前面三个Promise产生的错误
});
```
上面代码中，一共有三个 Promise 对象：一个由getJSON产生，两个由then产生。它们之中任何一个抛出的错误，都会被最后一个catch捕获。


*跟传统的try/catch代码块不同的是，如果没有使用catch方法指定错误处理的回调函数，Promise 对象抛出的错误不会传递到外层代码，即不会有任何反应。*
```
const someAsyncThing = function() {
  return new Promise(function(resolve, reject) {
    // 下面一行会报错，因为x没有声明
    resolve(x + 2);
  });
};

someAsyncThing().then(function() {
  console.log('everything is great');
});

setTimeout(() => { console.log(123) }, 2000);

// Uncaught (in promise) ReferenceError: x is not defined
// 123
```
上面代码中，someAsyncThing函数产生的 Promise 对象，内部有语法错误。浏览器运行到这一行，会打印出错误提示ReferenceError: x is not defined，但是不会退出进程、终止脚本执行，2 秒之后还是会输出123。这就是说，Promise 内部的错误不会影响到 Promise 外部的代码，通俗的说法就是“Promise 会吃掉错误”。


*resolve后抛出错误，将不会被捕获*
```
const promise = new Promise(function (resolve, reject) {
	resolve('ok');
	setTimeout(function () { throw new Error('test') }, 0)
});
promise
	.then(function (value) { console.log(value) })
	.catch(function(){ console.log('it is error') })
// ok
// Uncaught Error: test
```
上面代码中，Promise 指定在下一轮“事件循环”再抛出错误。到了那个时候，Promise 的运行已经结束了，所以这个错误是在 Promise 函数体外抛出的，会冒泡到最外层，成了未捕获的错误。
所以上面的 catch 不会执行



*建议Promise 对象后面要跟catch方法，这样可以处理 Promise 内部发生的错误。catch方法返回的还是一个 Promise 对象，因此后面还可以接着调用then方法。*
```
const someAsyncThing = function() {
  return new Promise(function(resolve, reject) {
    // 下面一行会报错，因为x没有声明
    resolve(x + 2);
  });
};

someAsyncThing()
.catch(function(error) {
  console.log('oh no', error);
})
.then(function() {
  console.log('carry on');
});
// oh no [ReferenceError: x is not defined]
// carry on
```
上面代码运行完catch方法指定的回调函数，会接着运行后面那个then方法指定的回调函数。如果没有报错，则会跳过catch方法。

而这时then方法报错，就与前面的catch无关了

catch方法之中，还能再抛出错误。这时如果后面还有catch就可以捕获。


# finally

finally方法用于指定不管 Promise 对象最后状态如何，都会执行的操作。finally方法的回调函数不接受任何参数，这意味着没有办法知道，前面的 Promise 状态到底是fulfilled还是rejected。
```
new Promise((resolve, reject) => {
	reject(1111)
}).finally(() => console.log(1))
```


# Promise.all()

用于将多个 Promise 实例，包装成一个新的 Promise 实例。
```
let p1 = new Promise((resolve,reject)=>{
	setTimeout(()=>resolve(), 0);
})
let p2 = new Promise((resolve,reject)=>{
	setTimeout(()=>resolve(), 0);
})
let p3 = new Promise((resolve,reject)=>{
	setTimeout(()=>reject(), 0);
})
const pAll1 = Promise.all([p1, p2]);
const pAll2 = Promise.all([p1, p3]);

pAll1
	.then(()=>console.log('pAll1 success'))
	.catch(()=>console.log('pAll1 fail'));
	
pAll2
	.then(()=>console.log('pAll2 success'))
	.catch(()=>console.log('pAll2 fail'));

// pAll1 success
// pAll2 fail
```
实例状态全变成fulfilled后，合并后实例的状态才会变成fulfilled；有一个实例的状态变为rejected，合并后实例的状态就会变成rejected

*一个实例的状态变成rejected后，即使其他实例还没返回状态，合并后实例的状态也会立即改变*


注意，如果作为参数的 Promise 实例，自己定义了catch方法，那么它一旦被rejected，并不会触发Promise.all()的catch方法。

比如上面代码的p3改为
```
let p3 = new Promise((resolve,reject)=>{
	setTimeout(()=>reject(), 0);
}).catch(()=>console.log(123));

// 123
// pAll2 success
```
这时p3的错误将不会被pAll2捕获，导致pAll2的状态变成fulfilled

而如果p3改为
```
let p3 = new Promise((resolve,reject)=>{
	setTimeout(()=>reject(), 0);
})
p3.catch(()=>console.log(123));

// 123
// pAll2 fail
```
这样写的话p3的错误还是会被捕获


# Promise.race()

用法和all()相同，不同的是只要有一个promise实例状态改变，合并后实例的状态就会改变，并且改变和率先改变的实例相同

比如上面的代码，如果改为race()，后p1和p2分别设为1000ms和2000ms，那么p1返回后pAll1就会打印出pAll1 success



# Promise.resolve()
```
Promise.resolve('foo')
// 等价于
new Promise(resolve => resolve('foo'))
```

参数：

1.参数是Promise实例，则不做修改，原封不动的返回该实例

2.参数是具有then方法的对象，Promise.resolve方法会将这个对象转为 Promise 对象，然后就立即执行thenable对象的then方法。
```
let thenable = {
  then: function(resolve, reject) {
    resolve(42);
  }
};

let p1 = Promise.resolve(thenable);
p1.then(function(value) {
  console.log(value);  // 42
});
```
3.参数不是具有then方法的对象，或根本就不是对象，则Promise.resolve方法返回一个新的 Promise 对象，状态为resolved。
```
const p = Promise.resolve('Hello');

p.then(function (s){
  console.log(s)
});
// Hello
```
4.不带参数，直接返回一个resolved状态的 Promise 对象。

需要注意的是，立即resolve的 Promise 对象，是在本轮“事件循环”（event loop）的结束时，而不是在下一轮“事件循环”的开始时。
```
setTimeout(function () {
  console.log('three');
}, 0);

Promise.resolve().then(function () {
  console.log('two');
});

console.log('one');

// one
// two
// three
```


# Promise.reject()

Promise.reject(reason)方法也会返回一个新的 Promise 实例，该实例的状态为rejected。
```
const p = Promise.reject('出错了');
// 等同于
const p = new Promise((resolve, reject) => reject('出错了'))

p.then(null, function (s) {
  console.log(s)
});
// 出错了
```

注意，Promise.reject()方法的参数，会原封不动地作为reject的理由，变成后续方法的参数。这一点与Promise.resolve方法不一致。
```
const thenable = {
  then(resolve, reject) {
    reject('出错了');
  }
};

Promise.reject(thenable)
.catch(e => {
  console.log(e === thenable)
})
// true
```
上面代码中，Promise.reject方法的参数是一个thenable对象，执行以后，后面catch方法的参数不是reject抛出的“出错了”这个字符串，而是thenable对象。


# Promise.try() 

我们希望不论函数f是同步函数还是异步操作，都想用 Promise 来处理它。因为这样就可以不管f是否包含异步操作，都用then方法指定下一步流程，用catch方法处理f抛出的错误。一般就会采用下面的写法。
```
const f = () => console.log('now');
Promise.resolve().then(f);
console.log('next');
// next
// now
```
上面的写法有一个缺点，就是如果f是同步函数，那么它会在本轮事件循环的末尾执行。

这里函数f是同步的，但是用 Promise 包装了以后，就变成异步执行了。

那么怎么让同步函数同步执行，异步函数异步执行，并且让它们具有统一的 API 呢？第一种写法是用async函数来写。

第一种写法是用async函数来写。
```
const f = () => console.log('now');
(async () => f())();
console.log('next');
// now
// next
```
上面代码中，第二行是一个立即执行的匿名函数，会立即执行里面的async函数，因此如果f是同步的，就会得到同步的结果；如果f是异步的，就可以用then指定下一步，就像下面的写法。
```
(async () => f())()
	.then(...)
```
需要注意的是，async () => f()会吃掉f()抛出的错误。所以，如果想捕获错误，要使用promise.catch方法。
```
(async () => f())()
	.then(...)
	.catch(...)
```

第二种写法是使用new Promise()。
```
const f = () => console.log('now');
(
  () => new Promise(
    resolve => resolve(f())
  )
)();
console.log('next');
// now
// next
```
上面代码也是使用立即执行的匿名函数，执行new Promise()。这种情况下，同步函数也是同步执行的。

鉴于这是一个很常见的需求，所以现在有一个提案，提供Promise.try方法替代上面的写法。
```
const f = () => console.log('now');
Promise.try(f);
console.log('next');
// now
// next
```

由于Promise.try为所有操作提供了统一的处理机制，所以如果想用then方法管理流程，最好都用Promise.try包装一下。这样有许多好处，其中一点就是可以更好地管理异常。
```
function getUsername(userId) {
  return database.users.get({id: userId})
  .then(function(user) {
    return user.name;
  });
}
```
上面代码中，database.users.get()返回一个 Promise 对象，如果抛出异步错误，可以用catch方法捕获，就像下面这样写。
```
database.users.get({id: userId})
.then(...)
.catch(...)
```
但是database.users.get()可能还会抛出同步错误（比如数据库连接错误，具体要看实现方法），这时你就不得不用try...catch去捕获。
```
try {
  database.users.get({id: userId})
  .then(...)
  .catch(...)
} catch (e) {
  // ...
}
```
上面这样的写法就很笨拙了，这时就可以统一用promise.catch()捕获所有同步和异步的错误。
```
Promise.try(database.users.get({id: userId}))
  .then(...)
  .catch(...)
```
事实上，Promise.try就是模拟try代码块，就像promise.catch模拟的是catch代码块。
